Workbook

Sheet Обобщена КС
A1: Възложител: Община Хисаря
A3: ОБЕКТ: Градски минерален и развлекателно рекреационен комплекс, находящ се в УПИ IX-1161, кв. 97 по плана на гр. Хисаря,Община Хисаря, Област Пловдив, ПИ 77270.504.1161 по КККР на гр. Хисаря
A5: ОБОБЩЕНА КОЛИЧЕСТВЕНА СМЕТКА
B9: Част: АС
A11: № | B11: ВИДОВЕ СМР | C11: един. мярка | D11: количество общо
A12: Част: Разрушаване на съществуващи постройки, басейни и други
A14: 1 | B14: Разрушаване на сгради и басейни с багер-чук - бетонови плочи, греди, стени, колони, основи | C14: м3 | D14: 962.8
A15: 2 | B15: Разрушаване на сгради и огради с верижен багер - тухлени стени, дървени покривни констр. и др. | C15: м3 | D15: 167.45
A16: 3 | B16: Разрушавене на съществуващи бетонови плочници с багер | C16: м2 | D16: 1158
A17: 4 | B17: Натоварване строителни отпадъци и транспорт на депо, включително такса депониране | C17: м3 | D17: 1362
A19: Б. Нови СМР
B20: I. Сграда
B21: ПОМЕЩЕНИЯ НА КОТА + 0,00
A22: 1 | B22: Възглавница от отсевки | C22: м3 | D22: ='Подробна КС -част АС'!H26 -> 96.322965
A23: 2 | B23: Топлоизолация от XPS с d = 5см | C23: м2 | D23: ='Подробна КС -част АС'!H31 -> 642.1531
A24: 3 | B24: Полиетиленово фолио | C24: м2 | D24: ='Подробна КС -част АС'!H33 -> 642.1531
A25: 4 | B25: Тухлена зидария от тухли Poroterm с d = 25см | C25: м3 | D25: ='Подробна КС -част АС'!H64 -> 123.66563
A26: 5 | B26: Тухлена зидария с тухли Poroterm с d = 12см | C26: м2 | D26: ='Подробна КС -част АС'!H116 -> 430.7895
A27: 6 | B27: Щендерна стена от панели Aquapanel - около парна баня и технич.помещ. | C27: м2 | D27: ='Подробна КС -част АС'!H124 -> 42.34
A28: 7 | B28: Тухлена зидария с d = 8 см | C28: м2 | D28: ='Подробна КС -част АС'!H130 -> 19.275
A29: 8 | B29: Конструкция от влагоустойчив гипскартон с d = 5см - инсталационни пакети в санитар.помещения | C29: м2 | D29: ='Подробна КС -част АС'!H134 -> 3.9
A30: 9 | B30: Преградни стени от HPL с d = 2см за WC "мъже" и WC "жени", вкл. врати 80/200 - общо 10 броя | C30: м2 | D30: ='Подробна КС -част АС'!H140 -> 42.6
A31: 10 | B31: Вътрешна мазилка по стени | C31: м2 | D31: ='Подробна КС -част АС'!H250 -> 1468.339
A32: 11 | B32: Вътрешна мазилка по тавани | C32: м2 | D32: ='Подробна КС -част АС'!H286 -> 386.8618
A33: 11а | B33: Вътрешна мазилка по таван на парна баня - с извита форма или подходящ наклон, за сигуряване на отвеждането на конденза | C33: м2 | D33: 10.23
A34: 12 | B34: Окачен таван от гипскартон с височина 20см от долен ръб ст.бетонна плоча - частично в зала за консумация - заведение | C34: м2 | D34: ='Подробна КС -част АС'!H295 -> 42.9237
A35: 13 | B35: Окачен таван от гипскартон с височина 70см от долен ръб ст.бетонна плоча - частично в зала за консумация - заведение | C35: м2 | D35: ='Подробна КС -част АС'!H301 -> 53.2605
A36: 14 | B36: Окачен таван от влагоустойчив гипскартон | C36: м2 | D36: ='Подробна КС -част АС'!H307 -> 25.54
A37: 15 | B37: Фаянс по стени | C37: м2 | D37: ='Подробна КС -част АС'!H362 -> 388.646
A38: 16 | B38: Грундиране по стени и тавани | C38: м2 | D38: ='Подробна КС -част АС'!H364 -> 1598.509
A39: 17 | B39: Боядисване с влагоустойчив латекс по тавани | C39: м2 | D39: ='Подробна КС -част АС'!H377 -> 72.34
A40: 18 | B40: Боядисване с интериорен акрилатен латекс ( Клас 1) | C40: м2 | D40: ='Подробна КС -част АС'!H393 -> 74.608
A41: 19 | B41: Боядисвене с латекс по стени и тавани | C41: м2 | D41: ='Подробна КС -част АС'!H395 -> 1451.561
A42: 20 | B42: Циментова замазка по подове с d=5см | C42: м2 | D42: ='Подробна КС -част АС'!H433 -> 519.43
A43: 21 | B43: Настилка от гранитогрес | C43: м2 | D43: ='Подробна КС -част АС'!H463 -> 424.1
A44: 22 | B44: Настилка от антистрип гранитогрес | C44: м2 | D44: ='Подробна КС -част АС'!H470 -> 54.99
A45: 23 | B45: Направа на проходен отвор на височ. 100мм от к.г.п. в стена и монтаж на декоративна решетка 200/100мм за осигур.приток на свеж въздух от общото помещение - за сауните | C45: бр | D45: ='Подробна КС -част АС'!H472 -> 2
A46: 24 | B46: Подсигуряване на вентилационна фуга с минимална височина 20мм под крилото на вратата на сауните | C46: бр | D46: ='Подробна КС -част АС'!H474 -> 2
B48: Обработка на дилтационна фуга :
A49: 1 | B49: Монтаж полистирол с d = 5 см във фугата | C49: м | D49: ='Подробна КС -част АС'!H477 -> 8.99
...

Sheet Подробна КС -част АС
A1: Възложител: Община Хисаря
A3: ОБЕКТ: Градски минерален и развлекателно рекреационен комплекс, находящ се в УПИ IX-1161, кв. 97 по плана на гр. Хисаря,Община Хисаря, Област Пловдив, ПИ 77270.504.1161 по КККР на гр. Хисаря
A5: ПОДРОБНА КОЛИЧЕСТВЕНА СМЕТКА
A7: Част: АС
A9: № | B9: ВИДОВЕ СМР | C9: един. мярка | D9: дължина | E9: ширина | F9: височина | G9: брой подобни части | H9: количество общо
A10: Част: Разрушаване на съществуващи постройки, басейни и други
A12: 1 | B12: Разрушаване на сгради и басейни с багер-чук - бетонови плочи, греди, стени, колони, основи | C12: м3 | H12: 962.8
A14: 2 | B14: Разрушаване на сгради и огради с верижен багер - тухлени стени, дървени покривни констр. и др. | C14: м3 | H14: 167.45
A16: 3 | B16: Разрушавене на съществуващи бетонови плочници с багер | C16: м2 | H16: 1158
A18: 4 | B18: Натоварване строителни отпадъци и транспорт на депо, включително такса депониране | C18: м3 | H18: 1362
A20: Б. Нови СМР
B21: I. Сграда
B22: ПОМЕЩЕНИЯ НА КОТА + 0,00
A23: 1 | B23: Възглавница от отсевки | C23: м3 | D23: 29.55 | E23: 8.99 | F23: 0.15 | G23: 1 | H23: =D23*E23*F23*G23 -> 39.848175
D24: 9.97 | E24: 10.1 | F24: 0.15 | G24: 1 | H24: =D24*E24*F24*G24 -> 15.10455
D25: 29.72 | E25: 9.28 | F25: 0.15 | G25: 1 | H25: =D25*E25*F25*G25 -> 41.37024
G26: общо : | H26: =SUM(H23:H25) -> 96.322965
A28: 2 | B28: Топлоизолация от XPS с d = 5см | C28: м2 | D28: 29.55 | E28: 8.99 | G28: 1 | H28: =D28*E28*G28 -> 265.6545
D29: 9.97 | E29: 10.1 | G29: 1 | H29: =D29*E29*G29 -> 100.697
D30: 29.72 | E30: 9.28 | G30: 1 | H30: =D30*E30*G30 -> 275.8016
G31: общо : | H31: =SUM(H28:H30) -> 642.1531
A33: 3 | B33: Полиетиленово фолио | C33: м2 | H33: =H31 -> 642.1531
A35: 4 | B35: Тухлена зидария от тухли Poroterm с d = 25см | C35: м3 | D35: 8.99 | E35: 0.25 | F35: 3.25 | G35: 1 | H35: =D35*E35*F35*G35 -> 7.304375
D36: 29.2 | E36: 0.25 | F36: 3.25 | G36: 1 | H36: =D36*E36*F36*G36 -> 23.725
D37: 1.8 | E37: 0.25 | F37: 3.25 | G37: 1 | H37: =D37*E37*F37*G37 -> 1.4625
D38: 1.43 | E38: 0.25 | F38: 3.25 | G38: 1 | H38: =D38*E38*F38*G38 -> 1.161875
D39: 9.6 | E39: 0.25 | F39: 3.25 | G39: 1 | H39: =D39*E39*F39*G39 -> 7.8
D40: 7.45 | E40: 0.25 | F40: 3.25 | G40: 1 | H40: =D40*E40*F40*G40 -> 6.053125
D41: 27.24 | E41: 0.25 | F41: 3.25 | G41: 1 | H41: =D41*E41*F41*G41 -> 22.1325
D42: 8.78 | E42: 0.25 | F42: 3.25 | G42: 1 | H42: =D42*E42*F42*G42 -> 7.13375
D43: 29.72 | E43: 0.25 | F43: 3.25 | G43: 1 | H43: =D43*E43*F43*G43 -> 24.1475
D44: 0.82 | E44: 0.25 | F44: 3.25 | G44: 1 | H44: =D44*E44*F44*G44 -> 0.66625
D45: 9.97 | E45: 0.25 | F45: 3.25 | G45: 1 | H45: =D45*E45*F45*G45 -> 8.100625
D46: 29.55 | E46: 0.25 | F46: 3.25 | G46: 1 | H46: =D46*E46*F46*G46 -> 24.009375
D47: 3.2 | E47: 0.25 | F47: 1.7 | G47: 1 | H47: =D47*E47*F47*G47 -> 1.36
... D54: 1.75 | E54: 0.25 | F54: 3.25 | G54: 1 | H54: =D54*E54*F54*G54 -> 1.421875
B55: спада се дограма :
B56: фасадна дограма : | D56: 0.9 | E56: 0.25 | F56: 3 | G56: 3 | H56: =-D56*E56*F56*G56 -> -2.025
D57: 3.6 | E57: 0.25 | F57: 0.65 | G57: 3 | H57: =-D57*E57*F57*G57 -> -1.755
D58: 3.6 | E58: 0.25 | F58: 2.85 | G58: 6 | H58: =-D58*E58*F58*G58 -> -15.39
...

Sheet КС - Конструкции
A1: Възложител: Община Хисаря
A3: ОБЕКТ: Градски минерален и развлекателно рекреационен комплекс, находящ се в УПИ IX-1161, кв. 97 по плана на гр. Хисаря,Община Хисаря, Област Пловдив, ПИ 77270.504.1161 по КККР на гр. Хисаря
A6: КОЛИЧЕСТВЕНА СМЕТКА
B8: Част: Строителни конструкции
B10: За хале с басейн:
B13: Изкоп – 1356м3
B14: Кофражни работи фундаменти и настилка – 893 м2
B15: Бетон фундаменти и настилка C20/25 –414 м3
B16: Армировка
B17: ф6.5 – N25–13 560 кг
B18: Стомана S235JR- 39407.6 кг
B19: Анкерна група 1 – 7х8 бр.
B20: За външен басейн и бар:
B21: Изкоп – 1578м3
B22: Кофражни работи– 542 м2
... B48: Армировка за стоманобетонова настилка - N8 -2750кг

Sheet Подробна КС- част ВиК
A1: КОЛИЧЕСТВЕНА СМЕТКА
A3: Обект : Градски минерален и развлекателно рекреационен комплекс, находящ се
A4: в УПИ IХ-1161, кв. 97 по плана на гр. Хисаря,Община Хисаря, Област Пловдив
A5: ПИ 77270.504.1161 по КККР на гр. Хисаря
B7: Част : В и К
B8: Фаза : Технически проект
B12: Водопроводно отклонение
A14: N | B14: Вид СМР | C14: ед.м. | D14: дъл. | E14: шир. | F14: вис. | G14: п. ч. | H14: кол.
A15: 1 | B15: Ръчен изкоп с шир. до 1,20 и дъл. до 2 м. | C15: м3 | D15: 5 | E15: 0.9 | F15: 1.15 | G15: 1 | H15: =D15*E15*F15*G15 -> 5.175
A16: 2 | B16: Дост.и полагане на непром. пъсък за подложка | C16: м3. | D16: 5 | E16: 0.9 | F16: 0.1 | G16: 1 | H16: =D16*E16*F16*G16 -> 0.45
A17: 3 | B17: Досавка на отсевки и засипване с уплътняване | C17: м3. | D17: 5 | E17: 0.65 | F17: 0.2 | G17: 1 | H17: =D17*E17*F17*G17 -> 0.65
A18: 4 | B18: Засипване и уплътняване на обратен насип | C18: м3. | H18: 4.08
A19: 5 | B19: Дост. и монт. на тр. СК Ф75 с охр. гарн. и чун. гърне | C19: бр. | H19: 1
A20: 6 | B20: Доставка и монтаж на намалител 75/50 РЕ-100 | C20: бр. | H20: 1
A21: 7 | B21: Доставка и монтаж на намалител 90/75 РЕ-100 | C21: бр. | H21: 1
A22: 8 | B22: Доставка и монтаж на универсално Ж Ф80 | C22: бр. | H22: 1
A23: 9 | B23: Доставка и монтаж на тръби Ф75/4.5 РЕ-100 PN10 | C23: м3. | H23: 5
A24: 10 | B24: Доставка и монтаж на тръби Ф90/5.4 РЕ-100 PN10 | C24: м3. | H24: 1
A25: 11 | B25: Дезинфекция и изпитване на външен водопровод | C25: м. | H25: 5
B27: Водомерна шахта
A29: № | B29: СМР | C29: Ед.м. | H29: Кол-во
A30: 1 | B30: Ръчен изкоп за строит. конструкция | C30: м3 | H30: 8.56
A31: 2 | B31: Направа на кофраж за стени с деб. над 15 см | C31: м2. | H31: 11.2
A32: 3 | B32: Бет. Кл.7.5 за дъно | C32: м3 | H32: 0.26
A33: 4 | B33: Бет. Кл.20 за дъно | C33: м3 | H33: 0.4
A34: 5 | B34: Бет. Кл.20 за стени | C34: м3 | H34: 1
A35: 6 | B35: Цим. замазка в два пласта по стени | C35: м2 | H35: 4.2
A36: 7 | B36: Стом. стъпала Ф25 | C36: бр. | H36: 3
A37: 8 | B37: Доставка и монтаж арматура Ст.АI | C37: кг. | H37: 185
A38: 9 | B38: Доставка и монтаж СК Ф 2 " с изпразн. | C38: бр. | H38: 1
A39: 10 | B39: Доставка и монтаж СК Ф 2 " | C39: бр. | H39: 1
A40: 11 | B40: Доставка и монтаж ВК 2 " | C40: бр. | H40: 1
A41: 12 | B41: Доставка и монтаж филтър Ф 2 " | C41: бр. | H41: 1
... A46: 17 | B46: Доставка и монтаж на ст. капак 100/100 - по детайл | C46: бр. | H46: 1
B49: Вътрешно водоснабдяване
B51: Вътрешно водоснабдяване - част I , западна
A53: № | B53: СМР | C53: Ед.м. | H53: Кол-во
A54: 1 | B54: Дост.и монтаж на полипроп. тръби - F20 | C54: м | H54: 35
A55: 2 | B55: Дост.и монтаж на полипроп. тръби - F25 | C55: м | H55: 16
A56: 3 | B56: Дост.и монтаж на полипроп. тръби - F32 | C56: м | H56: 20
...

Sheet КС - част ЕЛ
A1: КОЛИЧЕСТВЕНА СМЕТКА
A3: Обект: Градски минерален и развлекателно рекреационен комплекс, находящ се в УПИ IX-1161, кв. 97 по плана на гр. Хисаря, Община Хисаря, Област Пловдив, ПИ 77270.504.1161 по КККР на гр. Хисаря
A5: Част: Електро
A6: Фаза: ТП
A8: № | B8: Видове СМР | C8: мярка | D8: колич.
B9: Вътрешни ел. инсталации
A10: 1 | B10: Доставка ел. табла Тглавно, Трест.,Тфитн., Тсъбл. ,Тадм., Тбюф. , Тбар, Тосв.бас., Тп.асанс. | C10: бр. | D10: 9
A11: 2 | B11: Доставка ел. табла Твент.1, Твент.2, Твент.3, Ттехн. | C11: бр. | D11: 4
A12: 3 | B12: Монтаж на ел. табла в ниша | C12: бр. | D12: 7
A13: 4 | B13: Монтаж на ел. табла на стена | C13: бр. | D13: 4
A14: 5 | B14: Монтаж на ел. табло стоящо | C14: бр. | D14: 2
A15: 6 | B15: Доставка и монтаж на осв.тяло LED panel 48W, 1200/300мм, 4000К, с рамка за външен монтаж | C15: бр. | D15: 86
A16: 7 | B16: Доставка и монтаж на осв.тяло с LED пура 22W, 1200мм, 4000К, IP65, външен монтаж | C16: бр. | D16: 34
A17: 8 | B17: Доставка и монтаж на осв.тяло с 2бр. LED пура 22W, 1200мм, 4000К, IP65, външен монтаж | C17: бр. | D17: 73
A18: 9 | B18: Доставка и монтаж на LED линейно тяло - модул 10W, 868/22/37мм, 4000К, външен монтаж | C18: бр. | D18: 31
A19: 10 | B19: Доставка и монтаж на полилей LED 6x10вт | C19: бр. | D19: 2
A20: 11 | B20: Доставка и монтаж на плафониер LED 12W, със сензор за движение, 4000К, IP44 | C20: бр. | D20: 55
A21: 12 | B21: Доставка и монтаж на осв.тяло тип "луна" LED 8W, външен монтаж | C21: бр. | D21: 10
... A37: 28 | B37: Доставка и монтаж на ключ за осветление девиаторен | C37: бр. | D37: 24
A38: 29 | B38: Доставка и монтаж на ключ за осветление кръстат | D38: 1
A39: 30 | B39: Доставка и монтаж на ключ за осветление обикновен,противовл. | C39: бр. | D39: 3
A40: 31 | B40: Доставка и монтаж на ключ за осветление сериен,противовл. | C40: бр. | D40: 6
A41: 32 | B41: Доставка и монтаж на ключ за осветление девиаторен,противовл. | C41: бр. | D41: 10
A42: 33 | B42: Доставка и монтаж на бойлерно ел. табло | C42: бр. | D42: 4
A43: 34 | B43: Доставка и монтаж на разклонителна кутия противовлажна, IP 65 р.к 10/10 - осветл. рекламни пана | C43: бр. | D43: 6
A44: 35 | B44: Доставка и монтаж на фотоелемент "стенен монтаж" | C44: бр. | D44: 1
A45: 36 | B45: Доставка и монтаж на сензор движение/влага с регулируемо време,IP65 | C45: бр. | D45: 7
A46: 37 | B46: Доставка и монтаж на ДКУ | C46: бр. | D46: 4
A47: 38 | B47: Лампен излаз със СВТ 3х1,5мм2 открито - до 8м | C47: бр. | D47: 2
A48: 39 | B48: Лампен излаз със СВТ 3х1,5мм2 в PVCтр - до 8м | C48: бр. | D48: 4
A49: 40 | B49: Лампен излаз с ПВВ-МБ1 3х2,5мм2 скрито- до 20м | C49: бр. | D49: 22
A50: 41 | B50: Лампен излаз с ПВВ-МБ1 3х1,5мм2 скрито- до 10м | C50: бр. | D50: 172
... A105: 96 | B105: Доставка и монтаж пътнически асансьор, електрически без машинно, 630кг - 8 лица, 2 спирки | C105: бр. | D105: 1
B107: Мълниезащитна и заземителна инсталации
A108: 1 | B108: Полагане на неизолиран, полутвърд алумин.проводник ф8мм - ЕЕ/05/0035/А01/Al Mn Si на дистанционен носач открито | C108: м | D108: 85
A109: 2 | B109: Полагане на токоотвод от екструдиран, изолиран, полутвърд алумин. проводник ф8мм -ЕЕ/05/0045/А01/Al Mn Si - скрито в противопожарни ивици от минерална вата | C109: м | D109: 10
A110: 3 | B110: Доставка и монтаж мълниеприемник с изпреварващо действие - 60μs | C110: бр. | D110: 1
A111: 4 | B111: Доставка и монтаж на мачта с Н=3м | C111: бр. | D111: 1
A112: 5 | B112: Полагане на поцинкована шина 40/4 скрито | C112: м | D112: 3
A113: 6 | B113: Полагане на поцинкована шина 40/4 открито | C113: м | D113: 9
...

Sheet КС-технол. Кухня и мокър бюфет
A1: Възложител: Община Хисаря
A3: ОБЕКТ: Градски минерален и развлекателно рекреационен комплекс, находящ се в УПИ IX-1161, кв. 97 по плана на гр. Хисаря,Община Хисаря, Област Пловдив, ПИ 77270.504.1161 по КККР на гр. Хисаря
B5: КОЛИЧЕСТВЕНА СМЕТКА
A7: част: ТЕХНОЛОГИЯ : БИСТРО -ТОПЛА КУХНЯ И ВЪНШЕН МОКЪР БЮФЕТ
A9: № | B9: ВИДОВЕ СМР | C9: един. мярка | D9: количество общо
B10: БИСТРО -ТОПЛА КУХНЯ
A11: 1 | B11: Доставка и монтаж на хладилник N=0,20kW | C11: бр. | D11: 3
A12: 2 | B12: Доставка и монтаж на фризер N=0,25kW | C12: бр. | D12: 4
A13: 3 | B13: Даставка и монтаж на фризер СЖП N=0,25kW | C13: бр. | D13: 1
A14: 4 | B14: Доставка и монтаж на вертикална изложбена хладилник витрина за газирани напитки и вода N=0,20kW | C14: бр. | D14: 5
A15: 5 | B15: Доставка и монтаж на складов стелаж | C15: бр. | D15: 6
A16: 6 | B16: Доставка и монтаж на плот крайстенен с двугнездна мивка за месо и пилета с р-ри 2600/600/850мм | C16: бр. | D16: 1
A17: 7 | B17: Доставка и монтаж на плот крайстенен с едногнездна мивка за риба с р-ри 1700/600/850мм | C17: бр. | D17: 1
A18: 8 | B18: Доставка и монтаж на плот крайстенен с едногнездна мивка за зеленчук с р-ри 1700/600/850мм | C18: бр. | D18: 1
A19: 9 | B19: Доставка и монтаж на плот крайстенен с едногнездна мивка за зподготовка яйца с р-ри 900/500/850мм | C19: бр. | D19: 1
A20: 10 | B20: Доставка и монтаж на пластмасова скара | C20: бр. | D20: 1
A21: 11 | B21: Доставка и монтаж на зеленчукорезачна машина | C21: бр. | D21: 1
A22: 12 | B22: Доставка и монтаж на контейнер с капак | C22: бр. | D22: 7
... A47: 37 | B47: Доставка и монтаж на микровълнова печка | C47: бр. | D47: 1
A48: 38 | B48: Доставка и монтаж везна електронна
A49: 39 | B49: Доставка и монтаж на подвижна скара за тави | C49: бр. | D49: 1
A50: 40 | B50: Доставка и монтаж на микровълнова фурна | C50: бр. | D50: 1
A51: 41 | B51: Доставка и монтаж на касов апарат с фискална памет | C51: бр. | D51: 2
A52: 42 | B52: Доставка и монтаж на колонка за наливна бира | C52: бр. | D52: 1
A53: 43 | B53: Доставка и монтаж на ледогенератор | C53: бр. | D53: 1
A54: 44 | B54: Доставка и монтаж на кафемашина с две букси и кафемелачка | C54: бр. | D54: 1
A55: 45 | B55: Доставка и монтаж на рукванд L=1900мм | C55: бр. | D55: 1
A56: 46 | B56: Доставка и монтаж на апарат за минерална вода | C56: бр. | D56: 1
A57: 47 | B57: Доставка и монтаж на комбайн за бар, неръждаем-ледотрошачка, сокоизтисквачка,миксер и щейкър | C57: бр. | D57: 1
A58: 48 | B58: Направа и монтаж на бар-плот с двугнездна мивка по арх. детайл | C58: бр. | D58: 1
A59: 49 | B59: Доставка и монтаж на келнерски шкаф | C59: бр. | D59: 2
A60: 50 | B60: Доставка и монтаж на шкаф за дезинфекционни материали | C60: бр. | D60: 1
... A62: 52 | B62: Доставка и монтаж на гардеробчета | C62: бр. | D62: 4
B66: ВЪНШЕН МОКЪР БЮФЕТ
A68: № | B68: ВИДОВЕ СМР | C68: един. мярка | D68: количество общо
A69: 1 | B69: Направа и монтаж на бар-плот с три мивка по арх. детайл | C69: бр. | D69: 1
A70: 2 | B70: Доставка и монтаж на касов апарат с фискална памет | C70: бр. | D70: 1
A71: 3 | B71: Доставка и монтаж на апарат за минерална вода | C71: бр. | D71: 1
A72: 4 | B72: Доставка и монтаж на кафемашина с две букси и кафемелачка | C72: бр. | D72: 1
A73: 5 | B73: Доставка и монтаж на комбайн за бар, неръждаем-ледотрошачка, сокоизтисквачка,миксер и щейкър | C73: бр. | D73: 1
...

Sheet КС- технология басейни
A1: Възложител: Община Хисаря
A3: ОБЕКТ: Градски минерален и развлекателно рекреационен комплекс, находящ се в УПИ IX-1161, кв. 97 по плана на гр. Хисаря,Община Хисаря, Област Пловдив, ПИ 77270.504.1161 по КККР на гр. Хисаря
A6: КОЛИЧЕСТВЕНА СМЕТКА
A8: Част: Технология - басейни
A10: Количествена сметка №1
A13: № | B13: Наименование | C13: мярка | D13: К-во
B14: Обща количествена сметка за голям закрит басейн
A16: 1 | B16: Проф. ламиниран пясъчен филтър TEIDE PROFI LIGHT 1200; 30 m3/h/m2 , дебит 43 m3/h, св. d=90mm | C16: бр. | D16: 3
A17: 2 | B17: Чувал кварцов пясък 0.6 - 0.8 mm | C17: кг | D17: 3000
A18: 3 | B18: 6-пътен вентил 3" страничен монтаж | C18: бр. | D18: 3
A19: 4 | B19: Циркулационна помпа MAGNUS-4 300 [3.0 HP] 2,20kW | C19: бр. | D19: 3
A21: 5 | B21: Пластмасов специализиран фундамент за монтаж на | C21: бр. | D21: 6
B22: циркулационни помпи. Размер 395х230х200(h)мм. Включва гумени антивибрационни подложки.
A23: 6 | B23: Дюза дънна FLAT за керамика | C23: бр. | D23: 28
A24: 7 | B24: Подов сифон ф 110 | C24: бр. | D24: 2
A25: 8 | B25: Смукателна дюза за керамика HYDRODIF | C25: бр. | D25: 2
A26: 9 | B26: Автоматична дозаторна станция комплект, с регулатор DST-WDPHCL за регулиране на рН и дезинфектант (Свободен хлор) в басейн | C26: бр. | D26: 1
A27: 10 | B27: Бидон вертикален 500 л. H=1310mm ; D=730mm | C27: бр. | D27: 2
A28: 11 | B28: Помпа потопяема дренажна KONA 750PM [1.0 HP] [0.75 kW] | C28: бр. | D28: 1
B29: [8 m3/h,H=5]
A30: 12 | B30: Кран моторен BELIMO DN40-1 1/2", затваряне с пружина, норм.затворен, 24-230V за доливане на резервоара | C30: бр. | D30: 1
A32: 13 | B32: Редуцир-вентил 1 1/2" | C32: бр | D32: 1
A33: 14 | B33: Термопомпа модел iMAX 125 Inverter | C33: бр | D33: 1
A34: 15 | B34: PVC инсталация – тръби за високо налягане /10 атм./, кранове, фитинги и консумативи. | C34: к-т | D34: 1
A36: 16 | B36: Стълба SPECIAL OVERFLOW 4 мет. стъпала с неподхл. покритие + фланец, AISI 316L | C36: бр | D36: 2
A37: 17 | B37: Стълба SPECIAL OVERFLOW 5 мет. стъпала с неподхл. покритие + фланец, AISI 316L | C37: бр | D37: 2
A38: 18 | B38: Анкъри с фланец за монтаж на стълби без вкопаване - прав, SS.A-304. Комплект от 2 бр. | C38: бр | D38: 4
A44: Съставил: ……………………..
A45: / инж. Д. Мешков /
A48: Количествена сметка №2
A51: № | B51: Наименование | C51: мярка | D51: К-во
B52: Обща количествена сметка за външен басейн за възрастни с водни и въздушни ефекти
A54: 1 | B54: Проф. ламиниран пясъчен филтър TEIDE PROFI 1200; 50 m3/h/m2 , дебит 55m3/h, св. d=90mm | C54: бр. | D54: 4
A55: 2 | B55: Чувал кварцов пясък 0.6 - 0.8 mm | C55: кг | D55: 5400
A56: 3 | B56: Чувал кварцов пясък 0.6 - 0.8 mm | C56: бр | D56: 1100
A57: 4 | B57: Батерия за ръчно управление на пясъчен филтър с 5 крана, d=110mm | C57: бр. | D57: 4
A58: 5 | B58: Циркулационна помпа MAGNUS-4 400 [4.0 HP] 3,0kW | C58: бр. | D58: 4
A60: 6 | B60: Пластмасов специализиран фундамент за монтаж на | C60: бр | D60: 8
B61: циркулационни помпи. Размер 395х230х200(h)мм. Включва гумени антивибрационни подложки.
A62: 7 | B62: Дюза дънна FLAT за керамика | C62: бр. | D62: 38
...

Sheet КС- част ОВК
A1: Възложител: Община Хисаря
A3: ОБЕКТ: Градски минерален и развлекателно рекреационен комплекс, находящ се в УПИ IX-1161, кв. 97 по плана на гр. Хисаря,Община Хисаря, Област Пловдив, ПИ 77270.504.1161 по КККР на гр. Хисаря
B5: КОЛИЧЕСТВЕНА СМЕТКА
A7: част: ОВК
A9: № | B9: ВИДОВЕ СМР | C9: един. мярка | D9: количество общо
B11: ПЛУВЕН БАСЕЙН
A12: 1 | B12: Климатична камера - конструкции от алуминиеви профили и изолирани страници с дебелина 45мм, прахово покритие, включваща термопомпен агрегат, Scroll компресор Copeland с | C12: бр. | D12: 1
B16: 1.Дебит 14500м3/ч
B17: 2. Капацитет на изсушаване 99кг/ч
B18: Нагнетателна част:
B19: * секция смесителна с 3бр ПЖР
B20: * секция филтърна касетъчна с клас на филтрация G3
B21: * Секция рекуператорна с пластинчат рекуператор "въздух-въздух" притежаващ EUROVENT сертификат № 03.01.242 к-т с байпас и кондензна вана
B22: * Сенция топлообменна с изпарител/кондензатор с капацитет на изсушаване 99кг/ч
B23: * секция отоплителна с топлообменник от медни тръби и алуминиеви ламели с Qот=158кВт /вода 80/60оС/
B24: * Секция вентилаторна нагнетателна с дебит V=14500м3/ч, Нсв=400Ра, к-т с центробежен вентилатор с директно куплиран двигател тип Plug fan
B25: 3. Ел. мощност N=65,7 Kw
B26: Смукателна част:
B27: * секция смесителна с ПЖР
... B40: * пуск
A41: 2 | B41: Решетка вентилационна стенна хоризонтална с регулираща секция с р-ри 625х225 | C41: бр | D41: 24
A42: 3 | B42: Решетка вентилационна стенна хоризонтална с регулираща секция с р-ри 1200х250 | C42: бр | D42: 12
A43: 4 | B43: Неподвижна жалузийна решетка НЖР 1500х1000 | C43: бр | D43: 1
A44: 5 | B44: Шапка/зонт/ШП1200/600 | C44: бр | D44: 1
A45: 6 | B45: Мека връзка 1265х515 | C45: бр | D45: 2
A46: 7 | B46: Мека връзка 1180х1205 | C46: бр | D46: 1
A47: 8 | B47: Мека връзка 1265х614 | C47: бр | D47: 1
A48: 9 | B48: Шумозаглушител 1200х800 | C48: бр | D48: 2
A49: 10 | B49: Въздуховоди от поцинкована ламарина правоъгълни прави | C49: м2 | D49: 326
A50: 11 | B50: Въздуховоди от поцинкована ламарина правоъгълни фасонни | C50: м2 | D50: 171
A51: 12 | B51: Spiro въздуховоди ф315 | C51: м | D51: 17
A52: 13 | B52: Spiro въздуховоди ф400 | C52: м | D52: 15
... A86: 47 | B86: Механична наладка и ефективни измервания на климатична инсталация | C86: бр | D86: 1
B88: ЗАЛА ХРАНЕНЕ
A89: 1 | B89: Рекуперативен термопомпен блок | C89: бр | D89: 1
B90: 1.Дебит-2400m3/h
B91: 2.Пълна отоплителна мощност=31,6 kW
B92: 3.Пълна охладителна мощност=19,7 kW
B93: 4,Напор=350Pa
B94: 5,Е=70%
...

Sheet КС - фотоволтаична сист.
A1: Възложител: Община Хисаря
A3: ОБЕКТ: Градски минерален и развлекателно рекреационен комплекс, находящ се в УПИ IX-1161, кв. 97 по плана на гр. Хисаря,Община Хисаря, Област Пловдив, ПИ 77270.504.1161 по КККР на гр. Хисаря
A6: КОЛИЧЕСТВЕНА СМЕТКА
A9: Подобект: Фотоволтаична система
A13: № | B13: Наименование на материала / оборудването | C13: мярка | D13: Количество
A14: I. | B14: Основно оборудване
A15: 1 | B15: Доставка и монтаж на фотоволтаичен панел 540Wp (Monocrystalline) Jinko, Longi, JA Solar | C15: бр. | D15: 168
A16: =A15+1 -> 2 | B16: Доставка и монтаж на мрежов инвертор Huawei SUN2000-50KTL-M3 | C16: бр. | D16: 2
A17: =A16+1 -> 3 | B17: Доставка и монтаж на дата логер / Контролер Huawei SmartLogger 3000A | C17: бр. | D17: 1
A18: =A17+1 -> 4 | B18: Доставка и монтаж на смарт трифазен електромер Huawei DTSU666-H . В комплект с токови трансформатори (CT) 250A | C18: бр. | D18: 1
A19: II. | B19: Кабелни изделия и връзки
A20: 1 | B20: Доставка и изтегляне на соларен кабел 6 mm² – Червен (Плюс)- UV и термоустойчив за външен монтаж | C20: м | D20: 500
A21: =A20+1 -> 2 | B21: Доставка и изтегляне на соларен кабел 6 mm² – Черен (Минус)-UV и термоустойчив за външен монтаж | C21: м | D21: 500
A22: =A21+1 -> 3 | B22: Доставка и и изтегляне на силов меден кабел CBT-c (NYY) 5x35 mm²-За AC връзка от инверторите до ГРТ | C22: м | D22: 110
A23: =A22+1 -> 4 | B23: Доставка и и изтегляне на комуникационен кабел FTP Cat6 (или LiYCY 2x2x0.75)-За RS485 връзка инвертори - SmartLogger - Метер | C23: м | D23: 60
A24: =A23+1 -> 5 | B24: Доставка и изтегляне на заземителен меден проводник H07V-K 16 mm² (жълто-зелен)-За допълнително локално заземяване на инверторите | C24: м | D24: 20
A25: =A24+1 -> 6 | B25: Доставка и монтаж на соларни конектори MC4 (комплект мъжки + женски)-За кримпване на стринговете към инверторите (+резерва) | C25: чифт | D25: 30
A26: III. | B26: Електроапаратура и Табла (в ГРТ)
A27: 1 | B27: Доставка и монтаж на автоматичен прекъсвач 3P 100A, Крива C (10kA)-За защита на AC линията на всеки инвертор | C27: бр. | D27: 2
A28: 2 | B28: Доставка и монтаж на автоматичен прекъсвач NSX 3P 250A | C28: бр. | D28: 2
A29: 3 | B29: Доставка и монтаж на клеморед, шини и аксесоари за монтаж в ГРТ | C29: к-т | D29: 1
A30: IV. | B30: Тръбни трасета, крепежи и маркировка
A31: 1 | B31: Доставка и монтаж перфорирана кабелна скара горещопоцинкована СП 3000/60мм | C31: м | D31: 50
A32: =A31+1 -> 2 | B32: Доставка и монтаж на гофрирана тръба със защита от UV лъчи Ф32 -За защита на соларните кабели по покрив/стена | C32: м | D32: 250
A33: =A32+1 -> 3 | B33: Доставка и монтаж на твърда ПВЦ тръба (сива, UV защитена) Ф50/Ф63-За полагане на AC кабелите 5х35 по фасадата/стената | C33: м | D33: 60
A34: =A33+1 -> 4 | B34: Направа на суха разделка на силов кабел за сечение до 5х35мм2 | C34: бр. | D34: 4
A35: =A34+1 -> 5 | B35: Свързване на проводник към съоръжение дo 35мм2 | C35: бр. | D35: 10
A36: =A35+1 -> 6 | B36: Доставка и монтаж на скоби, крепежи и дюбели за тръбни трасета-За фиксиране на тръбите по термопанел | C36: к-кт | D36: 1
A37: =A36+1 -> 7 | B37: Доставка и монтаж на кабелни превръзки (свински опашки) - UV защитени (черни)-За привързване на кабелите под конструкцията на покрива | C37: бр. | D37: 500
A38: =A37+1 -> 8 | B38: Прозвъняване и подсъединяване жилата на соларни кабели за сечение до 6мм2 | C38: бр. | D38: 24
A39: =A38+1 -> 9 | B39: Доставка и монтаж на кабелни маркери (ПВЦ клипси с цифри/букви)-За етикетиране на стринговете | C39: к-кт | D39: 1
A40: IV. | B40: Заземителна инсталация
A41: 1 | B41: Доставка и монтаж на заземително въже AlMgSi ф8мм откритос крепежни елементи по покривна конструкция | C41: м | D41: 110
A42: 2 | B42: Направа на заземление с 2 броя зазем. колове 63/63/6 мм, L=1,54м за конструкцията на покривна соларна система | C42: бр. | D42: 2
A43: 3 | B43: Направа на заземление с 2 броя зазем. колове 63/63/6 мм, L=1,54м за соларни инвертори | C43: бр. | D43: 2
A44: V. | B44: Контролни измервания
A45: 1 | B45: Контролнии измервания на заземление | C45: бр. | D45: 3
A46: =A45+1 -> 2 | B46: Проверка изолацията на кабели с повишено напрежение посредством мегер | C46: бр. | D46: 28
A47: =A46+1 -> 3 | B47: Функционален пуск и настройка на системата | C47: чч | D47: 48
A48: =A47+1 -> 4 | B48: 72-часови проби на соларната инсталация | C48: чч | D48: 72
...

Sheet КС-паркоустр.и благоустройстр.
A1: Възложител: Община Хисаря
A3: ОБЕКТ: Градски минерален и развлекателно рекреационен комплекс, находящ се в УПИ IX-1161, кв. 97 по плана на гр. Хисаря,Община Хисаря, Област Пловдив, ПИ 77270.504.1161 по КККР на гр. Хисаря
A6: КОЛИЧЕСТВЕНА СМЕТКА
A8: ЧАСТ: ПАРКОУСТРОЙСТВО И БЛАГОУСТРОЙСТВО
A11: № | B11: СМР | C11: ед. мярка | D11: количество
B12: НАСТИЛКИ И СЪОРЪЖЕНИЯ
A13: 1 | B13: Подготовка на земната основа за настилки (подравняване и уплътняване) | C13: м2 | D13: 3235
A14: 2 | B14: Доставка на материали и полагане на основа от трошен камък с уплътняване | C14: м2 | D14: 3235
A15: 3 | B15: Доставка на материали и изграждане на декоративни пешеходни настилки | C15: м2 | D15: 1875
A16: 4 | B16: Доставка на материали и изграждане на тротоарни настилки | C16: м2 | D16: 280
A17: 5 | B17: Доставка на материали и изграждане на настилки на тревна фуга | C17: м2 | D17: 560
A18: 6 | B18: Доставка на материали и изграждане на усилени автомобилни настилки | C18: м2 | D18: 500
A19: 7 | B19: Доставка и монтаж на градински бордюри на бетонова основа | C19: м' | D19: 496
A20: 8 | B20: Доставка и монтаж на пътни бордюри на бетонова основа | C20: м' | D20: 88.4
A21: 9 | B21: Доставка на материали и изграждане на ударопоглъщащи настилки | C21: м2 | D21: 87
A22: 10 | B22: Доставка и монтаж на съоръжения за детска площадка | C22: бр. | D22: 1
A23: 11 | B23: Изграждане на волейболно игрище | C23: м2 | D23: 220
A24: 12 | B24: Изграждане на плувни басейни | C24: м2 | D24: 704
B25: СЪЩЕСТВУВАЩА РАСТИТЕЛНОСТ
A26: 13 | B26: Санитарни и оформящи резитби на съществуващи дървета (повдигане и оформяне на корони) | C26: бр. | D26: 20
A27: 14 | B27: Подмладителни резитби на съществуваща дървесна и храстова растителност | C27: бр. | D27: 8
A28: 15 | B28: Отсичане и премахване на дървета в лошо санитарно състояние с автовишка | C28: бр. | D28: 20
A29: 16 | B29: Събиране, временно складиране и изнасяне на растителните отпадъци от резитби и отсичане | C29: бр. | D29: 1
A30: 17 | B30: Транспорт и депониране на растителни отпадъци до депо за биоразградими отпадъци | C30: бр. | D30: 1
B31: ПОЧВОПОДГОТОВКА, ДЕЙНОСТИ ПО ОЗЕЛЕНЯВАНЕТО
A32: 18 | B32: Фино планиране и почистване на терена от плевели и камъни | C32: м2 | D32: 2380
A33: 19 | B33: Доставка на хумусна почва d=10 см | C33: куб.м | D33: 238
A34: 20 | B34: Разстилане на хумусна почва – механизирано | C34: куб.м | D34: 190.4
A35: 21 | B35: Разстилане на хумусна почва – ръчно (в труднодостъпни зони) | C35: куб.м | D35: 47.6
A36: 22 | B36: Затревяване (доставка на тревна смеска, засяване, валиране и първоначално поливане) | C36: м2 | D36: 2380
A37: 23 | B37: Засаждане на широколистна дървесна растителност | C37: бр. | D37: 74
A38: 24 | B38: Засаждане на иглолистна дървесна растителност | C38: бр. | D38: 13
A39: 25 | B39: Засаждане на храсти, треви и цветя | C39: бр. | D39: 1130
A40: 26 | B40: Укрепване на дървесна растителност | C40: бр. | D40: 87
A41: 27 | B41: Доставка и полагане на борови кори (мулч) под жив плет, Н=4 см | C41: куб.м | D41: 4.5
A42: 28 | B42: Изграждане на автоматизирана поливна система (АПС) | C42: компл. | D42: 1
B43: ДЕКОРАТИВНА РАСТИТЕЛНОСТ (ДОСТАВКА)
A44: 29 | B44: Cupressocyparis leylandii (лейланд), 100/120 см | C44: бр. | D44: 2
A45: 30 | B45: Pinus pinea (пиния), 180/220 см | C45: бр. | D45: 11
A46: 31 | B46: Albizia julibrissin "Summer chocolate" (шоколадова албиция), 180/220 см | C46: бр. | D46: 3
...
